let exception = Object()
let exceptionA = Object(exception)
let exceptionA.message = "A"
let exceptionB = Object(exception)
let exceptionB.message = "B"
let exceptionC = Object(exceptionB)
let exceptionC.message = "C"

let throwA = fn[exceptionA]():
    println("Good")
    yeet exceptionA
    println("Bad")

let throwA2 = fn[throwA]():
    println("Outer Good")
    throwA()
    println("Outer Bad")

let returnA = fn[exceptionA]():
    return exceptionA

let innerCatch = fn(call, type):
    try:
        call()
        println("Bad Inner")
    yoink type error:
        println("Caught in Inner ", error.message)

println("Stage 1")
try:
    try:
        throwA()
        println("BAD")
    yoink exceptionB error:
        println("Shouldn't catch B")
yoink exceptionA error:
    println("Should catch A")

println("Stage 2")
try:
    try:
        throwA()
        println("BAD")
    yoink exceptionB error:
        println("Shouldn't catch B")
yoink exception error:
    println("Should catch A")

println("Stage 3")
try:
    try:
        innerCatch(throwA, exceptionC)
        println("BAD")
    yoink exceptionB error:
        println("Shouldn't catch B")
yoink exception error:
    println("Should catch A")

println("Stage 4")
innerCatch(throwA2, exceptionA)

println("Stage 5")
try:
    try:
        yeet exceptionA
    yoink returnA() error:
        println("GOOD")
yoink exception error:
    println("Bad")